2019-11-25 19:10:29,564 : INFO : Machine : Mission Pinball Framework Core Engine v0.50.17
2019-11-25 19:10:29,580 : INFO : Machine : Command line arguments: {'pause': False, 'consoleloglevel': 20, 'no_load_cache': False, 'bcp': True, 'create_config_cache': True, 'production': False, 'logfile': 'logs\\2019-11-25-19-10-28-mpf-DESKTOP-I5I6D25.log', 'syslog_address': None, 'force_assets_load': False, 'mpfconfigfile': 'c:\\python34\\lib\\site-packages\\mpf\\mpfconfig.yaml', 'mc_file_name': None, 'force_platform': None, 'loglevel': 15, 'configfile': ['config.yaml'], 'text_ui': True}
2019-11-25 19:10:29,580 : INFO : Machine : MPF path: c:\python34\lib\site-packages\mpf
2019-11-25 19:10:29,580 : INFO : Machine : Machine path: D:\POKEMON - 3 - GYMS DISPLAYS
2019-11-25 19:10:29,580 : INFO : Machine : Platform: win32
2019-11-25 19:10:29,580 : INFO : Machine : Python executable location: c:\python34\python.exe
2019-11-25 19:10:29,580 : INFO : Machine : Python version: 3.4.4 (64-bit)
2019-11-25 19:10:31,723 : INFO : Machine : Machine config file #1: config.yaml
2019-11-25 19:10:31,729 : WARNING : ConfigProcessor : Cache file not found: C:\Users\MISSIO~1\AppData\Local\Temp\397fad0162a41b7db123b3957565a4ff.mpf_cache
2019-11-25 19:10:31,729 : INFO : ConfigProcessor : Loading config from file c:\python34\lib\site-packages\mpf\mpfconfig.yaml.
2019-11-25 19:10:32,212 : INFO : ConfigProcessor : Loading config: c:\python34\lib\site-packages\mpf\mpfconfig.yaml
2019-11-25 19:10:32,212 : INFO : ConfigProcessor : Loading config from file D:\POKEMON - 3 - GYMS DISPLAYS\config\config.yaml.
2019-11-25 19:10:32,639 : ERROR : root : YAML error found in file D:\POKEMON - 3 - GYMS DISPLAYS\config\config.yaml. Line 89,Position 9: mapping values are not allowed here
  in "D:\POKEMON - 3 - GYMS DISPLAYS\config\config.yaml", line 89, column 9
Traceback (most recent call last):
  File "c:\python34\lib\site-packages\mpf\file_interfaces\yaml_interface.py", line 194, in load
    config = self.process(f)
  File "c:\python34\lib\site-packages\mpf\file_interfaces\yaml_interface.py", line 220, in process
    return yaml.load(data_string, Loader=MpfLoader)
  File "c:\python34\lib\site-packages\ruamel\yaml\main.py", line 75, in load
    return loader.get_single_data()
  File "c:\python34\lib\site-packages\ruamel\yaml\constructor.py", line 57, in get_single_data
    node = self.get_single_node()
  File "c:\python34\lib\site-packages\ruamel\yaml\composer.py", line 46, in get_single_node
    document = self.compose_document()
  File "c:\python34\lib\site-packages\ruamel\yaml\composer.py", line 66, in compose_document
    node = self.compose_node(None, None)
  File "c:\python34\lib\site-packages\ruamel\yaml\composer.py", line 97, in compose_node
    node = self.compose_mapping_node(anchor)
  File "c:\python34\lib\site-packages\ruamel\yaml\composer.py", line 156, in compose_mapping_node
    item_value = self.compose_node(node, item_key)
  File "c:\python34\lib\site-packages\ruamel\yaml\composer.py", line 97, in compose_node
    node = self.compose_mapping_node(anchor)
  File "c:\python34\lib\site-packages\ruamel\yaml\composer.py", line 149, in compose_mapping_node
    while not self.check_event(MappingEndEvent):
  File "c:\python34\lib\site-packages\ruamel\yaml\parser_.py", line 118, in check_event
    self.current_event = self.state()
  File "c:\python34\lib\site-packages\ruamel\yaml\parser_.py", line 490, in parse_block_mapping_key
    if self.check_token(KeyToken):
  File "c:\python34\lib\site-packages\ruamel\yaml\scanner.py", line 130, in check_token
    self.fetch_more_tokens()
  File "c:\python34\lib\site-packages\ruamel\yaml\scanner.py", line 237, in fetch_more_tokens
    return self.fetch_value()
  File "c:\python34\lib\site-packages\ruamel\yaml\scanner.py", line 596, in fetch_value
    self.get_mark())
ruamel.yaml.scanner.ScannerError: mapping values are not allowed here
  in "D:\POKEMON - 3 - GYMS DISPLAYS\config\config.yaml", line 89, column 9

During handling of the above exception, another exception occurred:

Traceback (most recent call last):
  File "c:\python34\lib\site-packages\mpf\commands\game.py", line 208, in __init__
    MachineController(mpf_path, machine_path, vars(self.args)).run()
  File "c:\python34\lib\site-packages\mpf\core\machine.py", line 158, in __init__
    self._load_config()
  File "c:\python34\lib\site-packages\mpf\core\machine.py", line 427, in _load_config
    store_to_cache=self.options['create_config_cache'])
  File "c:\python34\lib\site-packages\mpf\core\config_processor.py", line 111, in load_config_files_with_cache
    ignore_unknown_sections)
  File "c:\python34\lib\site-packages\mpf\core\config_processor.py", line 131, in _load_config_file_and_return_loaded_files
    config = FileManager.load(filename, expected_version_str, True)
  File "c:\python34\lib\site-packages\mpf\core\file_manager.py", line 154, in load
    return interface.load(file, verify_version, halt_on_error)
  File "c:\python34\lib\site-packages\mpf\file_interfaces\yaml_interface.py", line 201, in load
    raise ValueError(msg)
ValueError: YAML error found in file D:\POKEMON - 3 - GYMS DISPLAYS\config\config.yaml. Line 89,Position 9: mapping values are not allowed here
  in "D:\POKEMON - 3 - GYMS DISPLAYS\config\config.yaml", line 89, column 9
