2019-09-25 22:36:16,085 : INFO : Machine : Mission Pinball Framework Core Engine v0.50.17
2019-09-25 22:36:16,100 : INFO : Machine : Command line arguments: {'text_ui': True, 'mpfconfigfile': 'c:\\python34\\lib\\site-packages\\mpf\\mpfconfig.yaml', 'logfile': 'logs\\2019-09-25-22-36-15-mpf-DESKTOP-I5I6D25.log', 'force_assets_load': False, 'production': False, 'no_load_cache': False, 'mc_file_name': None, 'consoleloglevel': 20, 'bcp': True, 'force_platform': None, 'create_config_cache': True, 'pause': False, 'loglevel': 15, 'syslog_address': None, 'configfile': ['config.yaml']}
2019-09-25 22:36:16,100 : INFO : Machine : MPF path: c:\python34\lib\site-packages\mpf
2019-09-25 22:36:16,100 : INFO : Machine : Machine path: D:\POKEMON - 2
2019-09-25 22:36:16,100 : INFO : Machine : Platform: win32
2019-09-25 22:36:16,100 : INFO : Machine : Python executable location: c:\python34\python.exe
2019-09-25 22:36:16,100 : INFO : Machine : Python version: 3.4.4 (64-bit)
2019-09-25 22:36:17,600 : INFO : Machine : Machine config file #1: config.yaml
2019-09-25 22:36:17,616 : INFO : ConfigProcessor : Loading config from cache: C:\Users\MISSIO~1\AppData\Local\Temp\442e40140b44297973c0b074da7880ab.mpf_cache
2019-09-25 22:36:17,631 : INFO : Machine : Initialise MPF.
2019-09-25 22:36:18,428 : INFO : FAST : Connecting to com4 at 921600bps
2019-09-25 22:36:18,475 : INFO : FAST : Connected! Processor: NET, Board Type: FP-CPU-002-2, Firmware: 01.01
2019-09-25 22:36:18,475 : WARNING : FAST : Not resetting FAST NET because firmware is currently broken.
2019-09-25 22:36:18,538 : INFO : FAST : Connecting to com5 at 921600bps
2019-09-25 22:36:18,570 : INFO : FAST : Connected! Processor: RGB, Board Type: FP-CPU-002-2, Firmware: 01.00
2019-09-25 22:36:19,007 : INFO : ConfigProcessor : Loading config from cache: C:\Users\MISSIO~1\AppData\Local\Temp\c8c985d122de6339937b15f5cde5ffe7.mpf_cache
2019-09-25 22:36:19,054 : INFO : ConfigProcessor : Loading config from cache: C:\Users\MISSIO~1\AppData\Local\Temp\6f2a382b9c765c6a1f408e05b1d50db1.mpf_cache
2019-09-25 22:36:19,054 : WARNING : ConfigProcessor : Config file in cache changed: D:\POKEMON - 2\modes\evolve_pichu\config\evolve_pichu.yaml
2019-09-25 22:36:19,054 : INFO : ConfigProcessor : Loading config from file D:\POKEMON - 2\modes\evolve_pichu\config\evolve_pichu.yaml.
2019-09-25 22:36:19,117 : ERROR : asyncio : Exception in callback EventManager._async_handler_done(<QueuedEvent>)(<Task finishe..., column 3',)>) at c:\python34\lib\site-packages\mpf\core\events.py:96
handle: <Handle EventManager._async_handler_done(<QueuedEvent>)(<Task finishe..., column 3',)>) at c:\python34\lib\site-packages\mpf\core\events.py:96>
Traceback (most recent call last):
  File "c:\python34\lib\site-packages\mpf\file_interfaces\yaml_interface.py", line 194, in load
    config = self.process(f)
  File "c:\python34\lib\site-packages\mpf\file_interfaces\yaml_interface.py", line 220, in process
    return yaml.load(data_string, Loader=MpfLoader)
  File "c:\python34\lib\site-packages\ruamel\yaml\main.py", line 75, in load
    return loader.get_single_data()
  File "c:\python34\lib\site-packages\ruamel\yaml\constructor.py", line 57, in get_single_data
    node = self.get_single_node()
  File "c:\python34\lib\site-packages\ruamel\yaml\composer.py", line 46, in get_single_node
    document = self.compose_document()
  File "c:\python34\lib\site-packages\ruamel\yaml\composer.py", line 66, in compose_document
    node = self.compose_node(None, None)
  File "c:\python34\lib\site-packages\ruamel\yaml\composer.py", line 97, in compose_node
    node = self.compose_mapping_node(anchor)
  File "c:\python34\lib\site-packages\ruamel\yaml\composer.py", line 156, in compose_mapping_node
    item_value = self.compose_node(node, item_key)
  File "c:\python34\lib\site-packages\ruamel\yaml\composer.py", line 97, in compose_node
    node = self.compose_mapping_node(anchor)
  File "c:\python34\lib\site-packages\ruamel\yaml\composer.py", line 156, in compose_mapping_node
    item_value = self.compose_node(node, item_key)
  File "c:\python34\lib\site-packages\ruamel\yaml\composer.py", line 97, in compose_node
    node = self.compose_mapping_node(anchor)
  File "c:\python34\lib\site-packages\ruamel\yaml\composer.py", line 149, in compose_mapping_node
    while not self.check_event(MappingEndEvent):
  File "c:\python34\lib\site-packages\ruamel\yaml\parser_.py", line 118, in check_event
    self.current_event = self.state()
  File "c:\python34\lib\site-packages\ruamel\yaml\parser_.py", line 490, in parse_block_mapping_key
    if self.check_token(KeyToken):
  File "c:\python34\lib\site-packages\ruamel\yaml\scanner.py", line 129, in check_token
    while self.need_more_tokens():
  File "c:\python34\lib\site-packages\ruamel\yaml\scanner.py", line 163, in need_more_tokens
    self.stale_possible_simple_keys()
  File "c:\python34\lib\site-packages\ruamel\yaml\scanner.py", line 307, in stale_possible_simple_keys
    "could not find expected ':'", self.get_mark())
ruamel.yaml.scanner.ScannerError: while scanning a simple key
  in "D:\POKEMON - 2\modes\evolve_pichu\config\evolve_pichu.yaml", line 67, column 5
could not find expected ':'
  in "D:\POKEMON - 2\modes\evolve_pichu\config\evolve_pichu.yaml", line 68, column 3

During handling of the above exception, another exception occurred:

Traceback (most recent call last):
  File "c:\python34\lib\asyncio\events.py", line 125, in _run
    self._callback(*self._args)
  File "c:\python34\lib\site-packages\mpf\core\events.py", line 99, in _async_handler_done
    future.result()
  File "c:\python34\lib\asyncio\futures.py", line 274, in result
    raise self._exception
  File "c:\python34\lib\asyncio\tasks.py", line 239, in _step
    result = coro.send(None)
  File "c:\python34\lib\site-packages\mpf\core\mode_controller.py", line 113, in load_modes
    self.machine.modes[mode] = self._load_mode(mode)
  File "c:\python34\lib\site-packages\mpf\core\mode_controller.py", line 262, in _load_mode
    config = self._load_mode_config(mode_string)
  File "c:\python34\lib\site-packages\mpf\core\mode_controller.py", line 180, in _load_mode_config
    store_to_cache=self.machine.options['create_config_cache'])
  File "c:\python34\lib\site-packages\mpf\core\config_processor.py", line 111, in load_config_files_with_cache
    ignore_unknown_sections)
  File "c:\python34\lib\site-packages\mpf\core\config_processor.py", line 131, in _load_config_file_and_return_loaded_files
    config = FileManager.load(filename, expected_version_str, True)
  File "c:\python34\lib\site-packages\mpf\core\file_manager.py", line 154, in load
    return interface.load(file, verify_version, halt_on_error)
  File "c:\python34\lib\site-packages\mpf\file_interfaces\yaml_interface.py", line 201, in load
    raise ValueError(msg)
ValueError: YAML error found in file D:\POKEMON - 2\modes\evolve_pichu\config\evolve_pichu.yaml. Line 68,Position 3: while scanning a simple key
  in "D:\POKEMON - 2\modes\evolve_pichu\config\evolve_pichu.yaml", line 67, column 5
could not find expected ':'
  in "D:\POKEMON - 2\modes\evolve_pichu\config\evolve_pichu.yaml", line 68, column 3
2019-09-25 22:36:19,507 : ERROR : root : Exception is not set.
Traceback (most recent call last):
  File "c:\python34\lib\site-packages\mpf\commands\game.py", line 208, in __init__
    MachineController(mpf_path, machine_path, vars(self.args)).run()
  File "c:\python34\lib\site-packages\mpf\core\machine.py", line 661, in run
    self.initialise_mpf()
  File "c:\python34\lib\site-packages\mpf\core\machine.py", line 653, in initialise_mpf
    if init.exception():
  File "c:\python34\lib\asyncio\futures.py", line 288, in exception
    raise InvalidStateError('Exception is not set.')
asyncio.futures.InvalidStateError: Exception is not set.
