2019-11-26 17:53:41,367 : INFO : Machine : Mission Pinball Framework Core Engine v0.50.17
2019-11-26 17:53:41,367 : INFO : Machine : Command line arguments: {'consoleloglevel': 20, 'mc_file_name': None, 'bcp': True, 'loglevel': 15, 'mpfconfigfile': 'c:\\python34\\lib\\site-packages\\mpf\\mpfconfig.yaml', 'text_ui': True, 'configfile': ['config.yaml'], 'syslog_address': None, 'force_assets_load': False, 'create_config_cache': True, 'force_platform': None, 'logfile': 'logs\\2019-11-26-17-53-41-mpf-DESKTOP-I5I6D25.log', 'production': False, 'pause': False, 'no_load_cache': False}
2019-11-26 17:53:41,367 : INFO : Machine : MPF path: c:\python34\lib\site-packages\mpf
2019-11-26 17:53:41,367 : INFO : Machine : Machine path: D:\POKEMON - 3 - GYMS DISPLAYS
2019-11-26 17:53:41,367 : INFO : Machine : Platform: win32
2019-11-26 17:53:41,367 : INFO : Machine : Python executable location: c:\python34\python.exe
2019-11-26 17:53:41,367 : INFO : Machine : Python version: 3.4.4 (64-bit)
2019-11-26 17:53:42,898 : INFO : Machine : Machine config file #1: config.yaml
2019-11-26 17:53:42,898 : INFO : ConfigProcessor : Loading config from cache: C:\Users\MISSIO~1\AppData\Local\Temp\397fad0162a41b7db123b3957565a4ff.mpf_cache
2019-11-26 17:53:42,960 : INFO : Machine : Initialise MPF.
2019-11-26 17:53:43,880 : INFO : FAST : Connecting to com4 at 921600bps
2019-11-26 17:53:43,943 : INFO : FAST : Connected! Processor: NET, Board Type: FP-CPU-002-2, Firmware: 01.01
2019-11-26 17:53:43,943 : WARNING : FAST : Not resetting FAST NET because firmware is currently broken.
2019-11-26 17:53:44,037 : INFO : FAST : Connecting to com5 at 921600bps
2019-11-26 17:53:44,099 : INFO : FAST : Connected! Processor: RGB, Board Type: FP-CPU-002-2, Firmware: 01.00
2019-11-26 17:53:44,755 : INFO : ConfigProcessor : Loading config from cache: C:\Users\MISSIO~1\AppData\Local\Temp\83c754771fb45e3fc54c6972ada6ad28.mpf_cache
2019-11-26 17:53:44,787 : WARNING : ConfigProcessor : Config file in cache changed: D:\POKEMON - 3 - GYMS DISPLAYS\modes\gym0\config\gym0.yaml
2019-11-26 17:53:44,787 : INFO : ConfigProcessor : Loading config from file D:\POKEMON - 3 - GYMS DISPLAYS\modes\gym0\config\gym0.yaml.
2019-11-26 17:53:44,818 : INFO : ConfigProcessor : Loading config: D:\POKEMON - 3 - GYMS DISPLAYS\modes\gym0\config\gym0.yaml
2019-11-26 17:53:44,818 : INFO : ConfigProcessor : Config file cache created: C:\Users\MISSIO~1\AppData\Local\Temp\7c39c18794ea7f1f8101ccbb93a960ae.mpf_cache
2019-11-26 17:53:44,834 : INFO : ConfigProcessor : Loading config from cache: C:\Users\MISSIO~1\AppData\Local\Temp\050cf1c6f86beee4aa95d4daa6cae486.mpf_cache
2019-11-26 17:53:44,849 : WARNING : ConfigProcessor : Cache file not found: C:\Users\MISSIO~1\AppData\Local\Temp\fec8123b1b217d56ad0888fe76304234.mpf_cache
2019-11-26 17:53:44,849 : INFO : ConfigProcessor : Loading config from file D:\POKEMON - 3 - GYMS DISPLAYS\modes\evolve_pichu\config\evolve_pichu.yaml.
2019-11-26 17:53:44,927 : INFO : ConfigProcessor : Loading config: D:\POKEMON - 3 - GYMS DISPLAYS\modes\evolve_pichu\config\evolve_pichu.yaml
2019-11-26 17:53:44,927 : INFO : ConfigProcessor : Config file cache created: C:\Users\MISSIO~1\AppData\Local\Temp\fec8123b1b217d56ad0888fe76304234.mpf_cache
2019-11-26 17:53:44,943 : WARNING : ConfigProcessor : Cache file not found: C:\Users\MISSIO~1\AppData\Local\Temp\a5b14625a1eebb95fe3d4d36c1f80403.mpf_cache
2019-11-26 17:53:44,943 : INFO : ConfigProcessor : Loading config from file D:\POKEMON - 3 - GYMS DISPLAYS\modes\pikachu\config\pikachu.yaml.
2019-11-26 17:53:45,052 : ERROR : asyncio : Exception in callback EventManager._async_handler_done(<QueuedEvent>)(<Task finishe...column 3\'',)>) at c:\python34\lib\site-packages\mpf\core\events.py:96
handle: <Handle EventManager._async_handler_done(<QueuedEvent>)(<Task finishe...column 3\'',)>) at c:\python34\lib\site-packages\mpf\core\events.py:96>
Traceback (most recent call last):
  File "c:\python34\lib\site-packages\mpf\file_interfaces\yaml_interface.py", line 194, in load
    config = self.process(f)
  File "c:\python34\lib\site-packages\mpf\file_interfaces\yaml_interface.py", line 220, in process
    return yaml.load(data_string, Loader=MpfLoader)
  File "c:\python34\lib\site-packages\ruamel\yaml\main.py", line 75, in load
    return loader.get_single_data()
  File "c:\python34\lib\site-packages\ruamel\yaml\constructor.py", line 59, in get_single_data
    return self.construct_document(node)
  File "c:\python34\lib\site-packages\ruamel\yaml\constructor.py", line 68, in construct_document
    for dummy in generator:
  File "c:\python34\lib\site-packages\ruamel\yaml\constructor.py", line 481, in construct_yaml_map
    value = self.construct_mapping(node)
  File "c:\python34\lib\site-packages\mpf\file_interfaces\yaml_interface.py", line 135, in construct_mapping
    format(key, key_node.start_mark))
KeyError: 'Key "mode_pikachu_started" was defined multiple times in config   in "D:\\POKEMON - 3 - GYMS DISPLAYS\\modes\\pikachu\\config\\pikachu.yaml", line 51, column 3'

During handling of the above exception, another exception occurred:

Traceback (most recent call last):
  File "c:\python34\lib\asyncio\events.py", line 125, in _run
    self._callback(*self._args)
  File "c:\python34\lib\site-packages\mpf\core\events.py", line 99, in _async_handler_done
    future.result()
  File "c:\python34\lib\asyncio\futures.py", line 274, in result
    raise self._exception
  File "c:\python34\lib\asyncio\tasks.py", line 239, in _step
    result = coro.send(None)
  File "c:\python34\lib\site-packages\mpf\core\mode_controller.py", line 113, in load_modes
    self.machine.modes[mode] = self._load_mode(mode)
  File "c:\python34\lib\site-packages\mpf\core\mode_controller.py", line 262, in _load_mode
    config = self._load_mode_config(mode_string)
  File "c:\python34\lib\site-packages\mpf\core\mode_controller.py", line 180, in _load_mode_config
    store_to_cache=self.machine.options['create_config_cache'])
  File "c:\python34\lib\site-packages\mpf\core\config_processor.py", line 111, in load_config_files_with_cache
    ignore_unknown_sections)
  File "c:\python34\lib\site-packages\mpf\core\config_processor.py", line 131, in _load_config_file_and_return_loaded_files
    config = FileManager.load(filename, expected_version_str, True)
  File "c:\python34\lib\site-packages\mpf\core\file_manager.py", line 154, in load
    return interface.load(file, verify_version, halt_on_error)
  File "c:\python34\lib\site-packages\mpf\file_interfaces\yaml_interface.py", line 208, in load
    raise ValueError(msg)
ValueError: Error found in file D:\POKEMON - 3 - GYMS DISPLAYS\modes\pikachu\config\pikachu.yaml: 'Key "mode_pikachu_started" was defined multiple times in config   in "D:\\POKEMON - 3 - GYMS DISPLAYS\\modes\\pikachu\\config\\pikachu.yaml", line 51, column 3'
2019-11-26 17:53:45,724 : ERROR : root : Exception is not set.
Traceback (most recent call last):
  File "c:\python34\lib\site-packages\mpf\commands\game.py", line 208, in __init__
    MachineController(mpf_path, machine_path, vars(self.args)).run()
  File "c:\python34\lib\site-packages\mpf\core\machine.py", line 661, in run
    self.initialise_mpf()
  File "c:\python34\lib\site-packages\mpf\core\machine.py", line 653, in initialise_mpf
    if init.exception():
  File "c:\python34\lib\asyncio\futures.py", line 288, in exception
    raise InvalidStateError('Exception is not set.')
asyncio.futures.InvalidStateError: Exception is not set.
