2019-11-25 19:39:33,302 : INFO : Machine : Mission Pinball Framework Core Engine v0.50.17
2019-11-25 19:39:33,318 : INFO : Machine : Command line arguments: {'force_platform': None, 'loglevel': 15, 'mc_file_name': None, 'production': False, 'pause': False, 'create_config_cache': True, 'consoleloglevel': 20, 'text_ui': True, 'logfile': 'logs\\2019-11-25-19-39-33-mpf-DESKTOP-I5I6D25.log', 'no_load_cache': False, 'syslog_address': None, 'mpfconfigfile': 'c:\\python34\\lib\\site-packages\\mpf\\mpfconfig.yaml', 'bcp': True, 'configfile': ['config.yaml'], 'force_assets_load': False}
2019-11-25 19:39:33,318 : INFO : Machine : MPF path: c:\python34\lib\site-packages\mpf
2019-11-25 19:39:33,318 : INFO : Machine : Machine path: D:\POKEMON - 3 - GYMS DISPLAYS
2019-11-25 19:39:33,318 : INFO : Machine : Platform: win32
2019-11-25 19:39:33,318 : INFO : Machine : Python executable location: c:\python34\python.exe
2019-11-25 19:39:33,318 : INFO : Machine : Python version: 3.4.4 (64-bit)
2019-11-25 19:39:34,771 : INFO : Machine : Machine config file #1: config.yaml
2019-11-25 19:39:34,787 : WARNING : ConfigProcessor : Config file in cache changed: D:\POKEMON - 3 - GYMS DISPLAYS\config\config.yaml
2019-11-25 19:39:34,787 : INFO : ConfigProcessor : Loading config from file c:\python34\lib\site-packages\mpf\mpfconfig.yaml.
2019-11-25 19:39:35,178 : INFO : ConfigProcessor : Loading config: c:\python34\lib\site-packages\mpf\mpfconfig.yaml
2019-11-25 19:39:35,178 : INFO : ConfigProcessor : Loading config from file D:\POKEMON - 3 - GYMS DISPLAYS\config\config.yaml.
2019-11-25 19:39:35,381 : INFO : ConfigProcessor : Loading config: D:\POKEMON - 3 - GYMS DISPLAYS\config\config.yaml
2019-11-25 19:39:35,724 : ERROR : root : Found a "mc_ready:" section in config file D:\POKEMON - 3 - GYMS DISPLAYS\config\config.yaml, but that section is not valid in machine config files.
Traceback (most recent call last):
  File "c:\python34\lib\site-packages\mpf\core\config_processor.py", line 147, in _load_config_file_and_return_loaded_files
    if config_type not in ConfigValidator.config_spec[k][
KeyError: 'mc_ready'

During handling of the above exception, another exception occurred:

Traceback (most recent call last):
  File "c:\python34\lib\site-packages\mpf\commands\game.py", line 208, in __init__
    MachineController(mpf_path, machine_path, vars(self.args)).run()
  File "c:\python34\lib\site-packages\mpf\core\machine.py", line 158, in __init__
    self._load_config()
  File "c:\python34\lib\site-packages\mpf\core\machine.py", line 427, in _load_config
    store_to_cache=self.options['create_config_cache'])
  File "c:\python34\lib\site-packages\mpf\core\config_processor.py", line 111, in load_config_files_with_cache
    ignore_unknown_sections)
  File "c:\python34\lib\site-packages\mpf\core\config_processor.py", line 156, in _load_config_file_and_return_loaded_files
    'files.'.format(k, filename, config_type))
ValueError: Found a "mc_ready:" section in config file D:\POKEMON - 3 - GYMS DISPLAYS\config\config.yaml, but that section is not valid in machine config files.
