2019-11-26 10:54:52,856 : INFO : Machine : Mission Pinball Framework Core Engine v0.50.17
2019-11-26 10:54:52,856 : INFO : Machine : Command line arguments: {'create_config_cache': True, 'logfile': 'logs\\2019-11-26-10-54-52-mpf-DESKTOP-I5I6D25.log', 'consoleloglevel': 20, 'bcp': True, 'mpfconfigfile': 'c:\\python34\\lib\\site-packages\\mpf\\mpfconfig.yaml', 'production': False, 'configfile': ['config.yaml'], 'force_assets_load': False, 'mc_file_name': None, 'text_ui': True, 'force_platform': None, 'loglevel': 15, 'no_load_cache': False, 'syslog_address': None, 'pause': False}
2019-11-26 10:54:52,856 : INFO : Machine : MPF path: c:\python34\lib\site-packages\mpf
2019-11-26 10:54:52,856 : INFO : Machine : Machine path: D:\POKEMON - 3 - GYMS DISPLAYS
2019-11-26 10:54:52,856 : INFO : Machine : Platform: win32
2019-11-26 10:54:52,856 : INFO : Machine : Python executable location: c:\python34\python.exe
2019-11-26 10:54:52,856 : INFO : Machine : Python version: 3.4.4 (64-bit)
2019-11-26 10:54:54,387 : INFO : Machine : Machine config file #1: config.yaml
2019-11-26 10:54:54,403 : WARNING : ConfigProcessor : Config file in cache changed: D:\POKEMON - 3 - GYMS DISPLAYS\config\config.yaml
2019-11-26 10:54:54,403 : INFO : ConfigProcessor : Loading config from file c:\python34\lib\site-packages\mpf\mpfconfig.yaml.
2019-11-26 10:54:54,778 : INFO : ConfigProcessor : Loading config: c:\python34\lib\site-packages\mpf\mpfconfig.yaml
2019-11-26 10:54:54,778 : INFO : ConfigProcessor : Loading config from file D:\POKEMON - 3 - GYMS DISPLAYS\config\config.yaml.
2019-11-26 10:54:55,163 : INFO : ConfigProcessor : Loading config: D:\POKEMON - 3 - GYMS DISPLAYS\config\config.yaml
2019-11-26 10:54:55,406 : INFO : ConfigProcessor : Loading config: D:\POKEMON - 3 - GYMS DISPLAYS\config\player_variables.yaml
2019-11-26 10:54:55,687 : INFO : ConfigProcessor : Loading config: D:\POKEMON - 3 - GYMS DISPLAYS\config\key_mapping.yaml
2019-11-26 10:54:55,687 : INFO : ConfigProcessor : Config file cache created: C:\Users\MISSIO~1\AppData\Local\Temp\397fad0162a41b7db123b3957565a4ff.mpf_cache
2019-11-26 10:54:55,718 : INFO : Machine : Initialise MPF.
2019-11-26 10:54:56,578 : INFO : FAST : Connecting to com4 at 921600bps
2019-11-26 10:54:56,609 : INFO : FAST : Connected! Processor: NET, Board Type: FP-CPU-002-2, Firmware: 01.01
2019-11-26 10:54:56,609 : WARNING : FAST : Not resetting FAST NET because firmware is currently broken.
2019-11-26 10:54:56,671 : INFO : FAST : Connecting to com5 at 921600bps
2019-11-26 10:54:56,718 : INFO : FAST : Connected! Processor: RGB, Board Type: FP-CPU-002-2, Firmware: 01.00
2019-11-26 10:54:57,368 : WARNING : ConfigProcessor : Config file in cache changed: D:\POKEMON - 3 - GYMS DISPLAYS\modes\pichu\config\pichu.yaml
2019-11-26 10:54:57,368 : INFO : ConfigProcessor : Loading config from file D:\POKEMON - 3 - GYMS DISPLAYS\modes\pichu\config\pichu.yaml.
2019-11-26 10:54:57,477 : INFO : ConfigProcessor : Loading config: D:\POKEMON - 3 - GYMS DISPLAYS\modes\pichu\config\pichu.yaml
2019-11-26 10:54:57,477 : INFO : ConfigProcessor : Config file cache created: C:\Users\MISSIO~1\AppData\Local\Temp\050cf1c6f86beee4aa95d4daa6cae486.mpf_cache
2019-11-26 10:54:57,493 : INFO : ConfigProcessor : Loading config from cache: C:\Users\MISSIO~1\AppData\Local\Temp\10f8871b1481fbf59bf30d5b3d29537e.mpf_cache
2019-11-26 10:54:57,665 : INFO : ConfigProcessor : Loading config from cache: C:\Users\MISSIO~1\AppData\Local\Temp\7f23218709f44a41086dfd04f42f7c3f.mpf_cache
2019-11-26 10:54:57,743 : WARNING : ConfigProcessor : Cache file not found: C:\Users\MISSIO~1\AppData\Local\Temp\7c39c18794ea7f1f8101ccbb93a960ae.mpf_cache
2019-11-26 10:54:57,743 : INFO : ConfigProcessor : Loading config from file D:\POKEMON - 3 - GYMS DISPLAYS\modes\gym0\config\gym0.yaml.
2019-11-26 10:54:57,774 : ERROR : asyncio : Exception in callback EventManager._async_handler_done(<QueuedEvent>)(<Task finishe..., column 2',)>) at c:\python34\lib\site-packages\mpf\core\events.py:96
handle: <Handle EventManager._async_handler_done(<QueuedEvent>)(<Task finishe..., column 2',)>) at c:\python34\lib\site-packages\mpf\core\events.py:96>
Traceback (most recent call last):
  File "c:\python34\lib\site-packages\mpf\file_interfaces\yaml_interface.py", line 194, in load
    config = self.process(f)
  File "c:\python34\lib\site-packages\mpf\file_interfaces\yaml_interface.py", line 220, in process
    return yaml.load(data_string, Loader=MpfLoader)
  File "c:\python34\lib\site-packages\ruamel\yaml\main.py", line 75, in load
    return loader.get_single_data()
  File "c:\python34\lib\site-packages\ruamel\yaml\constructor.py", line 57, in get_single_data
    node = self.get_single_node()
  File "c:\python34\lib\site-packages\ruamel\yaml\composer.py", line 46, in get_single_node
    document = self.compose_document()
  File "c:\python34\lib\site-packages\ruamel\yaml\composer.py", line 66, in compose_document
    node = self.compose_node(None, None)
  File "c:\python34\lib\site-packages\ruamel\yaml\composer.py", line 97, in compose_node
    node = self.compose_mapping_node(anchor)
  File "c:\python34\lib\site-packages\ruamel\yaml\composer.py", line 149, in compose_mapping_node
    while not self.check_event(MappingEndEvent):
  File "c:\python34\lib\site-packages\ruamel\yaml\parser_.py", line 118, in check_event
    self.current_event = self.state()
  File "c:\python34\lib\site-packages\ruamel\yaml\parser_.py", line 504, in parse_block_mapping_key
    token.start_mark)
ruamel.yaml.parser_.ParserError: while parsing a block mapping
  in "D:\POKEMON - 3 - GYMS DISPLAYS\modes\gym0\config\gym0.yaml", line 2, column 1
expected <block end>, but found '<block mapping start>'
  in "D:\POKEMON - 3 - GYMS DISPLAYS\modes\gym0\config\gym0.yaml", line 14, column 2

During handling of the above exception, another exception occurred:

Traceback (most recent call last):
  File "c:\python34\lib\asyncio\events.py", line 125, in _run
    self._callback(*self._args)
  File "c:\python34\lib\site-packages\mpf\core\events.py", line 99, in _async_handler_done
    future.result()
  File "c:\python34\lib\asyncio\futures.py", line 274, in result
    raise self._exception
  File "c:\python34\lib\asyncio\tasks.py", line 239, in _step
    result = coro.send(None)
  File "c:\python34\lib\site-packages\mpf\core\mode_controller.py", line 113, in load_modes
    self.machine.modes[mode] = self._load_mode(mode)
  File "c:\python34\lib\site-packages\mpf\core\mode_controller.py", line 262, in _load_mode
    config = self._load_mode_config(mode_string)
  File "c:\python34\lib\site-packages\mpf\core\mode_controller.py", line 180, in _load_mode_config
    store_to_cache=self.machine.options['create_config_cache'])
  File "c:\python34\lib\site-packages\mpf\core\config_processor.py", line 111, in load_config_files_with_cache
    ignore_unknown_sections)
  File "c:\python34\lib\site-packages\mpf\core\config_processor.py", line 131, in _load_config_file_and_return_loaded_files
    config = FileManager.load(filename, expected_version_str, True)
  File "c:\python34\lib\site-packages\mpf\core\file_manager.py", line 154, in load
    return interface.load(file, verify_version, halt_on_error)
  File "c:\python34\lib\site-packages\mpf\file_interfaces\yaml_interface.py", line 201, in load
    raise ValueError(msg)
ValueError: YAML error found in file D:\POKEMON - 3 - GYMS DISPLAYS\modes\gym0\config\gym0.yaml. Line 14,Position 2: while parsing a block mapping
  in "D:\POKEMON - 3 - GYMS DISPLAYS\modes\gym0\config\gym0.yaml", line 2, column 1
expected <block end>, but found '<block mapping start>'
  in "D:\POKEMON - 3 - GYMS DISPLAYS\modes\gym0\config\gym0.yaml", line 14, column 2
2019-11-26 10:54:58,462 : ERROR : root : Exception is not set.
Traceback (most recent call last):
  File "c:\python34\lib\site-packages\mpf\commands\game.py", line 208, in __init__
    MachineController(mpf_path, machine_path, vars(self.args)).run()
  File "c:\python34\lib\site-packages\mpf\core\machine.py", line 661, in run
    self.initialise_mpf()
  File "c:\python34\lib\site-packages\mpf\core\machine.py", line 653, in initialise_mpf
    if init.exception():
  File "c:\python34\lib\asyncio\futures.py", line 288, in exception
    raise InvalidStateError('Exception is not set.')
asyncio.futures.InvalidStateError: Exception is not set.
